Workbook

Sheet Danh mục
A1: Tiến độ | C1: Người
A2: Chưa bắt đầu | C2: Dev A
A3: Đang làm | C3: Dev B
A4: Hoàn thành
A5: Trễ hạn
A6: Đã hủy

Sheet Trạng thái xuất phát
A1: TRẠNG THÁI REPO NGÀY 20/09/2026 — ĐIỂM XUẤT PHÁT THẬT CỦA 21 NGÀY
A2: Kiểm kê bằng script trên chính repo, không chép từ tài liệu. Đọc sheet này TRƯỚC khi đọc lịch: nhiều việc mà bản kế hoạch cũ ghi là 'phải làm' thì thực ra đã xong, và ngược lại có những thứ tưởng đã có thì đang là khung rỗng. Cột 'Hệ quả lên lịch' trỏ về đúng ngày phải xử lý.
A4: Hạng mục | B4: Trạng thái | C4: Bằng chứng trong repo | D4: Hệ quả lên lịch 21 ngày
A5: Migration Track B | B5: ✅ ĐÃ CÓ THẬT | C5: 9 file Flyway V201–V209, 654 dòng, dải V2xx. Schema knowledge / ai / integration. 6 bảng: knowledge_documents, knowledge_chunks, ai_interactions, ai_feedback, ai_tool_calls, mcp_servers. | D5: Ngày 1 CHẠY migration chứ không THIẾT KẾ migration. Migration mới bắt đầu từ V210, không sửa V201–V209.
A6: Cô lập tenant ở tầng CSDL | B6: ✅ ĐÃ CÓ THẬT | C6: V207 ENABLE + FORCE ROW LEVEL SECURITY trên cả 6 bảng, policy tenant_isolation dùng USING + WITH CHECK qua hàm ai.current_tenant(). V206 GRANT cho role ai_app, không GRANT gì trên schema Track A. | D6: Ngày 1 chỉ cần viết TEST chứng minh nó hoạt động — hiện chưa có test nào.
A7: Số chiều vector | B7: ✅ ĐÃ CHỐT | C7: V203 dòng 17: embedding vector(1024). ADR-0015 mục 5 chốt 1024, KHÔNG phải 768 như Master Plan §4.2. | D7: Ngày 2 phải chọn encoder cho ra đúng 1024 chiều. Đây là ràng buộc cứng, không phải lựa chọn.
A8: Chỉ mục truy hồi | B8: ✅ ĐÃ CÓ THẬT | C8: V203 có ix_chunk_fts (GIN trên content_segmented). ai-service/scripts/create_hnsw_index.sql có HNSW vector_cosine_ops m=16 ef_construction=64 CONCURRENTLY — chạy TAY sau khi nạp dữ liệu. | D8: Hai làn của hybrid search đã sẵn ở tầng CSDL. Ngày 6 chỉ cần viết câu SQL gộp. HNSW chạy lần đầu ở Ngày 5.
A9: CI + cổng chặn ML runtime | B9: ✅ ĐÃ CÓ THẬT | C9: .github/workflows/ci.yml đang chạy: compileall, kiểm chiều phụ thuộc bằng grep neo đầu dòng, ruff, docker build, cổng 3 gói onnxruntime|torch|xgboost → exit 1, chặn import sklearn trong src/. Job inference có cổng ngược: không được có torch|sentence-transformers|flagembedding. | D9: Ngày 1 KHÔNG viết CI từ đầu. Việc còn lại: bật exit 1 cho cổng dung lượng image (hiện mới ::warning::).
A10: Hạ tầng dev | B10: ✅ ĐÃ CÓ THẬT | C10: docker-compose.yml (Postgres+pgvector, Redis, Kafka, ZooKeeper, profile observability), scripts/init-db.sql, scripts/create-topics.sh (5 topic), scripts/migrate-ai.sh. | D10: Ngày 1 chỉ chạy, không dựng. Nhớ bẫy hai listener: kafka:9092 từ trong mạng Docker, localhost:29092 từ máy chủ.
A11: Cấu hình + log + metric + DI | B11: ✅ ĐÃ CÓ THẬT | C11: src/ai/config.py (embedding_dim=1024, rrf_k=60, retrieve_top_k=20, lru_cache), telemetry/logging.py (JSON log + ContextVar trace_id/tenant_id), telemetry/metrics.py (4 metric Prometheus đã khai), api/deps.py (get_tenant_id FAIL-CLOSED), schemas.py, exceptions.py, entrypoint.py (workers=1), health.py. | D11: Dùng lại ngay, đừng viết lại. 4 metric đã khai nhưng CHƯA nơi nào gọi .observe() — gắn ở Ngày 8.
A12: Hai Dockerfile + compose suy luận | B12: ✅ ĐÃ CÓ THẬT | C12: ai-service/Dockerfile (python:3.11-slim, non-root) và inference/Dockerfile. inference/compose.inference.yml định nghĩa đủ 3 service ai-embed:8081 / ai-rerank:8082 / ai-classify:8083, OMP_NUM_THREADS = cpus, requests==limits, healthcheck /ready. | D12: Ngày 2 chỉ cần viết CODE cho 3 service; hạ tầng container đã xong.
A13: Phân tách requirements 3 tầng | B13: ✅ ĐÃ CÓ THẬT | C13: ai-service/requirements/base.txt KHÔNG có onnxruntime/torch/xgboost (có langgraph, psycopg, pgvector, aiokafka, pymupdf, pyvi). inference/requirements/base.txt có onnxruntime, không torch. notebooks/requirements.txt có torch, transformers, xgboost, skl2onnx, shap — đúng nơi. | D13: Giữ nguyên ranh giới này. scikit-learn có mặt trong ai-service là phụ thuộc GIÁN TIẾP của pyvi, được ADR-0015 chấp nhận có chủ đích — nhưng cấm import sklearn trong src/.
A14: Tài liệu quyết định | B14: ✅ ĐÃ CÓ THẬT | C14: 17 ADR (0001–0016 + template). ADR-0015 và ADR-0016 (19/09/2026) chốt cấu trúc src/, tách tầng suy luận, vector 1024, schema knowledge.*, cổng CI 3 gói, role ai_app, không tạo ai.lead_features. docs/contracts/README.md ghi bảng 'đã chốt' và 'còn treo'. | D14: Bảy điều đã chốt — xem sheet 'Hướng dẫn & Ghi chú'. ĐỪNG MỞ LẠI.
A15: Code AI (RAG, LangGraph, extraction, scoring) | B15: 🟡 KHUNG RỖNG | C15: 30/42 file .py trong ai-service/src chỉ có docstring đặc tả, 0 dòng code: src/ai/service.py (facade), rag/{ingest,retrieve,rerank,generate}, orchestrator/ (graph.py/state.py/nodes.py CHƯA TỒN TẠI), extraction/, guardrails/, inference/clients.py, db/models/, db/repositories/, events/, scoring/, clustering/. Tổng src/: 42 file, 859 dòng, chỉ 166 câu lệnh thực thi. | D15: Toàn bộ Tuần 1–2 là viết phần này. Docstring đã ghi sẵn ngưỡng nghiệm thu — đọc trước khi code.
... A25: Phụ thuộc vào Track A | B25: ⚠️ CHƯA XONG | C25: docs/contracts/de-xuat-track-a-lead-scores-outcome.md (3 cột rule_score/outcome/outcome_at) soạn 19/09 nhưng CHƯA GỬI. Bảng engagement.handoff_events chưa tồn tại. Consumer analytics-cg chưa có. | D25: Gửi đề xuất NGAY Ngày 1. UC030 cần 3 cột ở Ngày 9, UC014 cần handoff_events ở Ngày 12, UC039 cần analytics-cg ở Ngày 15.

Sheet Kế hoạch 21 ngày
A1: Tuần | B1: Ngày | C1: Ngày lịch | D1: Người phụ trách | E1: Tên Task / Use Case | F1: Điểm xuất phát (repo 20/09) | G1: Chi tiết công việc (Action Items) | H1: Minh chứng báo cáo | I1: Tiến độ
A2: Tuần 1 | B2: Ngày 1 | C2: T2 21/09 | D2: Dev A | E2: Dựng CSDL thật từ V201–V209 + test cách ly tenant đầu tiên | F2: ĐÃ CÓ: 9 file migration Flyway V201–V209 (654 dòng), RLS ENABLE + FORCE trên cả 6 bảng (V207), hàm ai.current_tenant(), scripts/migrate-ai.sh, scripts/init-db.sql, docker-compose.yml, ai-service/scripts/create_hnsw_index.sql. CHƯA CÓ: chưa từng chạy Flyway thật (không có flyway_schema_history); ai-service/tests/ có ĐÚNG 0 test. | G2: CODE: docker compose up -d postgres redis kafka (cả 4 phải healthy) → bash scripts/migrate-ai.sh → kiểm \dt knowledge.* ai.* integration.* ra đủ 6 bảng, \di ra đủ chỉ mục của V202–V209. LƯU Ý: create_hnsw_index.sql chạy TAY và chạy SAU khi đã nạp dữ liệu (CONCURRENTLY) — hôm nay chỉ xác nhận script đúng cú pháp, chưa chạy. CODE: tests/integration/test_rls.py — ba ca bắt buộc: (a) tenant A đọc chunk của B trả RỖNG; (b) pool.acquire() mà KHÔNG SET LOCAL app.tenant_id cũng trả RỖNG (fail-closed, không phải trả tất cả); (c) SELECT current_user trả ai_app chứ không phải crm_owner — chủ bảng bypass RLS kể cả khi đã FORCE. CODE: thêm job test RLS vào .github/workflows/ci.yml dùng testcontainers (dev.txt đã có sẵn gói này). KHÔNG có test này xanh thì không ai được đi tiếp sang Ngày 2. GỬI TRACK A NGAY HÔM NAY: docs/contracts/de-xuat-track-a-lead-scores-outcome.md (3 cột rule_score / outcome / outcome_at). Ngày 9 mới cần nhưng Track A cần thời gian viết migration V1xx — gửi muộn là chặn UC030. | H2: Ảnh chụp flyway_schema_history đủ 9 dòng V201–V209; danh sách 6 bảng + chỉ mục; test_rls.py 3/3 ca XANH trong CI; ảnh chụp SELECT current_user = ai_app; email/tin nhắn đã gửi đề xuất 3 cột cho Track A kèm dấu thời gian. | I2: Chưa bắt đầu
A3: Tuần 1 | B3: Ngày 1 | C3: T2 21/09 | D3: Dev B | E3: Chốt 4 mâu thuẫn hợp đồng + siết cổng CI dung lượng image | F3: ĐÃ CÓ: .github/workflows/ci.yml chạy thật với cổng chặn ML runtime 3 gói (onnxruntime|torch|xgboost) + chặn import sklearn trong src/; docs/openapi/ai-service-to-java-core.yaml có ~22 path nhưng gần như chỉ có summary + TODO; docs/events/ có 5 schema JSON; scripts/create-topics.sh tạo 5 topic crm.*.v1. CHƯA CÓ: body/response của mọi endpoint; cổng dung lượng image mới là ::warning:: chứ chưa exit 1. | G3: CHỐT 1 — TÊN ENDPOINT. Hiện lệch hai bộ: src/ai/service.py ghi /v1/ai/chat, /v1/ai/kb/documents; OpenAPI ghi /v1/answer, /v1/documents/ingest. Chọn MỘT bộ (đề xuất /v1/ai/** theo Master Plan §2.5 và rule ai-service.md: /v1/ai/** có phiên bản, /health /ready /metrics không) rồi sửa cả hai nơi cho khớp. CHỐT 2 — BỘ TOPIC KAFKA. Repo có 5 topic crm.*.v1, Master Plan §2.6 khai 8 topic. Không thể hoãn nữa vì consumer đầu tiên viết ở Ngày 5. Chốt danh sách, cập nhật scripts/create-topics.sh + docs/events/, nhớ crm.deal.closed (vòng phản hồi outcome của UC030) chưa có trong CẢ HAI bộ. CHỐT 3 — CHỖ ĐẶT BỘ VÀNG. tests/eval/golden_set.jsonl (rule rag-eval.md) hay data/golden_qa.jsonl (CLAUDE.md gốc)? Hai file đang tồn tại song song, một cái rỗng một cái chưa có. Chọn một, xoá nhắc tới cái kia. CHỐT 4 — CỠ TẬP TEST NGƯỜI THẬT. ADR-0016 ghi không dưới 250; lịch 21 ngày 2 người chỉ vừa 200. Chốt 200 và ghi lý do vào ADR phạm vi — im lặng rồi nộp 200 mới là thứ mất điểm. CODE: điền requestBody + responses cho 8 path trong phạm vi; bật exit 1 cho cổng dung lượng image. | H3: 4 quyết định ghi thành ADR-0017 (một ADR gộp, mục Bối cảnh trích đúng file:dòng đang lệch); redocly lint xanh trên ai-service-to-java-core.yaml; create-topics.sh chạy ra đúng số topic đã chốt; CI đỏ khi image vượt ngưỡng (chứng minh cổng có hiệu lực). | I3: Chưa bắt đầu
A4: Tuần 1 | B4: Ngày 2 | C4: T3 22/09 | D4: Dev A | E4: Tầng truy cập CSDL có RLS + export encoder 1024 chiều sang ONNX INT8 | F4: ĐÃ CÓ: src/ai/config.py chạy được (embedding_dim=1024, rrf_k=60, retrieve_top_k=20); src/api/deps.py có get_tenant_id fail-closed. KHUNG RỖNG: src/ai/db/ chỉ có docstring, 0 model, 0 repository. CHƯA CÓ: artifact .onnx nào, artifacts/MODEL_REGISTRY.md bảng đăng ký toàn '(chưa có)'. | G4: CODE: src/ai/db/session.py — pool asyncpg; SET LOCAL app.tenant_id đặt NGAY SAU pool.acquire() và trong CÙNG transaction với truy vấn. Đây là bẫy connection pool: SET không có LOCAL sẽ dính lại trên kết nối và rò sang request của tenant khác. Kết nối bằng role ai_app. CODE: repository cho knowledge_documents và knowledge_chunks; mọi truy vấn vector lọc tenant_id NGAY TRONG truy vấn, không lọc ở Python (ADR-0007, bề mặt T6). R&D (Kaggle, CHẠY CPU): chọn encoder cho ra vector ĐÚNG 1024 chiều — ràng buộc cứng từ V203 dòng 17, không đổi được vì cột đã là vector(1024). Export ONNX, lượng tử hoá INT8 động per-channel, ghi sha256 vào artifacts/MODEL_REGISTRY.md. TEST — CỔNG PARITY: cosine giữa fp32 và INT8 trên 500 câu phải ≥ 0,995. Không đạt thì dừng, đổi model, không đi tiếp. | H4: PARITY COSINE INT8 vs fp32 ≥ 0,995 (bảng + histogram); xác nhận số chiều vector = 1024 bằng một lượt INSERT thật vào knowledge_chunks (sai chiều là lỗi ngay ở tầng CSDL); MODEL_REGISTRY.md có dòng đầu tiên thật với sha256; test RLS vẫn xanh sau khi thêm session.py. | I4: Chưa bắt đầu
A5: Tuần 1 | B5: Ngày 2 | C5: T3 22/09 | D5: Dev B | E5: Hiện thực tầng suy luận thật + BUỔI CHUNG gõ tập test người thật | F5: ĐÃ CÓ: inference/Dockerfile, inference/compose.inference.yml định nghĩa đủ 3 service ai-embed:8081 / ai-rerank:8082 / ai-classify:8083 với OMP_NUM_THREADS = cpus và requests==limits; inference/requirements/base.txt có onnxruntime, KHÔNG có torch. STUB: inference/src/entrypoint.py hiện raise NotImplementedError — container build được nhưng crash ngay. session.py, bench_cpu.py, roles/*.py đều 0 dòng code. src/ai/inference/clients.py cũng chỉ docstring. CHƯA CÓ: data/intent_test_human.jsonl, artifacts/DATA_HASHES.txt. | G5: CODE: inference/src/session.py — make_session() ghim intra_op = OMP_NUM_THREADS, inter_op_num_threads = 1. ONNX Runtime đọc số CPU của NODE chứ không đọc limits của container: để mặc định thì p95 có thể tệ gấp 3 lần mà không log nào báo. CODE: entrypoint.py thật (MODEL_ROLE=embed|rerank|classify), roles/embed.py, /ready với 3 bất biến §3.4.2 — model_id khớp cấu hình, thứ tự cột khớp meta.json, số luồng khớp cpus — FAIL-CLOSED trả 503 nếu lệch. CODE: src/ai/inference/clients.py ba backend remote | mock | offline; mock có seed cố định cho mọi endpoint để Track A chạy song song không phải chờ. DATA — BUỔI CHUNG CẢ HAI NGƯỜI, ~3 GIỜ: gõ tay 200 câu hỏi thật theo 7 nhánh ý định, có cả câu KHÔNG DẤU, viết tắt, sai chính tả. Đóng băng data/intent_test_human.jsonl + ghi sha256 vào artifacts/DATA_HASHES.txt. Từ lúc đóng băng, file này KHÔNG BAO GIỜ được sửa để cải thiện điểm. | H5: Ảnh chụp /ready trả 503 khi cố tình để model_id lệch; docker compose -f inference/compose.inference.yml up lên được cả 3 container healthy; TẬP TEST 200 MẪU ĐÃ ĐÓNG BĂNG + hash SHA-256 trong Git. Không có tập này thì mọi con số macro-F1 về sau đều là ảo. | I5: Chưa bắt đầu
A6: Tuần 1 | B6: Ngày 3 | C6: T4 23/09 | D6: Dev A | E6: UC018 — Tải lên tài liệu tri thức | F6: ĐÃ CÓ: bảng knowledge.knowledge_documents (V202) với status, file_path, version, description (V209); ràng buộc ck_doc_failed; src/api/v1/router.py tồn tại nhưng 0 route. CHƯA CÓ: route nào, bộ tệp mẫu nào. | G6: DATA: bộ 20 tệp mẫu PDF/DOCX/TXT/MD/HTML + 5 tệp lỗi (quá 20 MB, sai MIME, PDF scan không trích được text). Đây cũng là nguồn của golden set Ngày 6 nên chọn tài liệu có nội dung nghiệp vụ thật (bảng giá, chính sách bảo hành, quy trình đổi trả), không lấy văn bản ngẫu nhiên. CODE: POST theo tên endpoint đã chốt Ngày 1 — kiểm phần mở rộng + dung lượng + hạn mức max_documents của gói; ghi bản ghi PENDING kèm title 3–300 ký tự, description ≤ 500, language vi|en; lưu tệp theo đường dẫn CÓ CHỨA tenant_id (cô lập ngay ở tầng kho lưu trữ chứ không chỉ ở truy vấn); trùng tiêu đề thì tăng version, không ghi đè; trả 202 + job_id; phát sự kiện với khoá phân vùng = tenant_id. TEST: 5 mã lỗi tách bạch 413 (tệp > 20 MB) / 415 (sai định dạng) / 409 (chạm hạn mức gói) / 422 / PARSE_NO_TEXT_EXTRACTED — đây là điểm 1 trong 'Mười một điểm cần chốt' của đặc tả UC. | H6: Bảng 5 ca lỗi × mã HTTP đúng (25/25 tệp mẫu); ảnh chụp đường dẫn lưu trữ có tenant_id; ngưỡng cảnh báo hạn mức 80% và chặn 100%; 20 tệp mẫu đã vào repo (đã kiểm không chứa dữ liệu cá nhân). | I6: Chưa bắt đầu
A7: Tuần 1 | B7: Ngày 3 | C7: T4 23/09 | D7: Dev B | E7: UC022 (1/4) — Dữ liệu huấn luyện + gán nhãn chéo | F7: ĐÃ CÓ: tập test người thật 200 mẫu đóng băng từ Ngày 2; notebooks/requirements.txt đã liệt kê đủ torch, transformers, sentence-transformers, xgboost, skl2onnx. CHƯA CÓ: notebooks/ không có file .ipynb nào. | G7: DATA: sinh 3.000 mẫu train bằng LLM theo phân bổ BẮT BUỘC — 25% lịch sự đầy đủ / 25% chat ngắn viết tắt / 20% KHÔNG DẤU / 15% lỗi chính tả / 10% pha tiếng Anh / 5% emoji. KHỬ TRÙNG LẶP gần giống: không làm thì khoảng 30% là bản sao và mọi chỉ số bị thổi phồng. DATA: gán nhãn chéo tập test người thật cùng Dev A — mỗi người gán ĐỘC LẬP rồi mới đối chiếu, đo Cohen's kappa, ngồi lại giải quyết mọi ca bất đồng. Bất đồng nhãn ở đây biến thành sai số hệ thống ở MỌI chỉ số về sau. CODE: notebook 04_data_router.ipynb có đủ 4 điều kiện tái lập — ghim seed, ghim phiên bản thư viện, ghi hash dữ liệu, xuất metric ra file. | H7: Số mẫu train trước/sau khử trùng lặp; biểu đồ phân bố 6 văn phong so với tỉ lệ mục tiêu; COHEN'S KAPPA giữa 2 người gán nhãn — số liệu này chỉ có khi làm 2 người, đáng đưa vào báo cáo. | I7: Chưa bắt đầu
A8: Tuần 1 | B8: Ngày 4 | C8: T5 24/09 | D8: Dev A | E8: UC019 (1/2) — Phân tích cú pháp, chuẩn hoá tiếng Việt, chia đoạn | F8: ĐÃ CÓ: requirements/base.txt đã có pymupdf, python-docx, trafilatura, pyvi, unidecode; knowledge_chunks có sẵn content_segmented + ix_chunk_fts (GIN) từ V203. KHUNG RỖNG: src/ai/rag/ingest/ chỉ có 1 dòng docstring. | G8: CODE: parser đa định dạng chạy trong ProcessPoolExecutor ĐÚNG 1 WORKER (PDF hỏng làm treo tiến trình — tách tiến trình là để giết được nó mà không giết cả service). CODE: normalize_vi xử lý zero-width, NFD/NFC, 'hoà'/'hòa', ký tự lặp. MỘT HÀM DUY NHẤT dùng cho CẢ hai đầu — lúc nạp và lúc truy vấn. Hai hàm khác nhau là lỗi thầm lặng: không có exception, chỉ có recall tụt. CODE: chia đoạn ~500 token, GIỮ số trang và heading để trích dẫn được ('Bảng giá 2026 > Gói Pro'); ghi content_segmented bằng pyvi; tsvector bọc unaccent trong hàm IMMUTABLE; dựng phrase query — toán tử liền kề cho cụm nhiều âm tiết, phép OR giữa các từ (dùng AND sẽ trả rỗng ngay khi khách gõ thừa một từ). MIGRATION: nếu cần cột mới thì bắt đầu từ V210 — V201–V209 đã chạy, không sửa file cũ. TEST: unit test normalize_vi; build_tsquery với câu KHÔNG DẤU; PDF scan phải chuyển FAILED kèm error_message. | H8: Bảng tỉ lệ trích xuất thành công theo từng định dạng; phân bố số token mỗi đoạn (trung vị ~500); tỉ lệ khớp truy vấn KHÔNG DẤU trước/sau khi bật unaccent; ảnh chụp một chunk có heading đầy đủ. | I8: Chưa bắt đầu
A9: Tuần 1 | B9: Ngày 4 | C9: T5 24/09 | D9: Dev B | E9: UC022 (2/4) — Huấn luyện nhánh C + phóng nhánh B chạy GPU qua đêm | F9: ĐÃ CÓ: ai-embed chạy được từ Ngày 2 nên nhánh C có sẵn nguồn vector. QUYẾT ĐỊNH PHẠM VI: chỉ làm 2 trong 3 nhánh của Master Plan §5.9 — bỏ nhánh A (TF-IDF + LinearSVC). | G9: CODE nhánh C: embedding từ ai-embed + k-NN/logistic. Router và retrieval dùng chung MỘT lời gọi embedding nên chi phí độ trễ THÊM cho router bằng KHÔNG — đây là lợi thế cấu trúc, không phải phương án phụ. CODE nhánh B: notebook 05_train_router_xlmr.ipynb — fine-tune XLM-R base trên tập tổng hợp đã khử trùng lặp. CUỐI NGÀY: đẩy notebook nhánh B lên Kaggle GPU, PHÓNG CHẠY QUA ĐÊM — 3–4 giờ máy, 0 giờ người. Đây là lý do giữ được nhánh B mà không tốn thêm ngày làm việc nào. GHI ADR lý do bỏ nhánh A: A là baseline RẺ NHẤT và là nhánh duy nhất chắc chắn lọt ngân sách 60 ms (p95 vài ms). Bỏ A nghĩa là nếu B quá chậm thì chỉ còn C làm lưới an toàn — may là C tái dùng ai-embed nên lưới này khá chắc. Không ghi ADR thì báo cáo bị đọc là thiếu sót chứ không phải quyết định. | H9: Kết quả nhánh C trên tập test người thật 200 mẫu; log Kaggle xác nhận nhánh B đang chạy; 2 notebook có đủ 4 điều kiện tái lập; ADR ghi rõ lý do bỏ nhánh A kèm đánh đổi. | I9: Chưa bắt đầu
A10: Tuần 1 | B10: Ngày 5 | C10: T6 25/09 | D10: Dev A | E10: UC019 (2/2) — Nhúng theo lô + worker Kafka + DLQ | F10: ĐÃ CÓ: requirements có aiokafka; bộ topic đã chốt Ngày 1. STUB: src/worker/main.py hiện raise NotImplementedError (dòng 38); src/worker/consumers/ rỗng; src/api/main.py còn 4 TODO trong lifespan (khởi động Kafka consumer, middleware trace, exception handler, /metrics). | G10: CODE: /v1/embed/batch lô 32 đoạn — không gom toàn bộ vector vào RAM; semaphore giới hạn ĐÚNG 1 job nạp đồng thời (dùng chung hàng đợi với UC020). CODE: worker thật thay cho NotImplementedError — consumer với enable_auto_commit=False (auto-commit đánh dấu xử lý xong TRƯỚC khi thực sự xong; một lần pod chết là mất sự kiện), max_poll_interval_ms=600000, xác nhận offset SAU khi xử lý thành công; chống trùng bằng INSERT ... ON CONFLICT DO NOTHING vào bảng processed_events — 0 dòng ảnh hưởng thì bỏ qua sự kiện. CODE: chuyển tài liệu sang READY + chunk_count + indexed_at; lỗi vĩnh viễn đẩy sang DLQ; endpoint trả 6 bước tiến độ của job. CODE: chạy create_hnsw_index.sql LẦN ĐẦU sau khi đã có chunk thật (m=16, ef_construction=64, CONCURRENTLY). TEST: ép lỗi lược đồ để kiểm chứng DLQ; restart worker giữa chừng, job phải hoàn tất hoặc được nhận lại nguyên vẹn. | H10: Thời gian nạp tài liệu 100 trang (đo thật); throughput đoạn/giây; ảnh chụp sự kiện nằm trong DLQ; biểu đồ 6 bước tiến độ của một job; \di xác nhận chỉ mục HNSW đã tồn tại trên knowledge_chunks. | I10: Chưa bắt đầu
A11: Tuần 1 | B11: Ngày 5 | C11: T6 25/09 | D11: Dev B | E11: UC022 (3/4) — So sánh hai nhánh có khoảng tin cậy + chốt nhánh ship + export ONNX | F11: ĐÃ CÓ: kết quả nhánh B chạy qua đêm; ai-classify đã dựng khung từ Ngày 2 (roles/classify.py còn rỗng). | G11: TEST: đánh giá CẢ HAI nhánh trên CÙNG tập test người thật đã đóng băng Ngày 2; macro-F1 kèm KTC bootstrap; so sánh THEO CẶP (paired bootstrap, KTC 95%) chứ không so hai con số trần — hai model chênh 1,5 điểm trên 200 mẫu rất có thể chỉ là nhiễu; vẽ confusion matrix cho từng nhánh. QUY TẮC CHỐT (§5.9): thắng rõ ràng (chênh > 3 điểm macro-F1 và KTC không chồng lấn) thì ship nhánh đó; không chênh có ý nghĩa thì ship nhánh có p95 THẤP NHẤT — tiêu chí DUY NHẤT để phá thế hoà. Lưu ý riêng của cặp B/C: XLM-R base 278M chạy CPU rất dễ vượt ngân sách 60 ms, nên hoàn toàn có thể B thắng về macro-F1 mà vẫn phải ship C. Đó KHÔNG phải thất bại mà là một kết quả đáng viết vào báo cáo. TEST: chọn ngưỡng bỏ phiếu trắng TỪ ĐƯỜNG CONG KIỂM ĐỊNH tại điểm độ chính xác phần giữ lại ≈ 0,95. CODE: export nhánh thắng sang ONNX INT8, viết roles/classify.py thật — SINH RA ĐÃ Ở ĐÚNG CHỖ, không viết in-process rồi di trú sau; MODEL_CARD_router ghi cho CẢ HAI nhánh. | H11: BẢNG 2 NHÁNH × macro-F1 × KTC 95% × p95 × kích thước model — đưa CẢ HAI vào báo cáo chứ không chỉ nhánh thắng; 2 confusion matrix; ĐỒ THỊ đường cong abstention và điểm đã chọn; ADR chốt nhánh nêu rõ thắng về chất lượng hay thắng về độ trễ; parity ONNX đạt. | I11: Chưa bắt đầu
A12: Tuần 1 | B12: Ngày 6 | C12: T7 26/09 | D12: Dev A | E12: Hybrid Search + bộ vàng v1 + khai thác dữ liệu fine-tune (phóng GPU qua đêm) | F12: ĐÃ CÓ: config.py đã ghim rrf_k=60 và retrieve_top_k=20; V203 đã có sẵn cả chỉ mục HNSW lẫn GIN — hai làn truy hồi đã sẵn sàng ở tầng CSDL. KHUNG RỖNG: src/ai/rag/retrieve/ 1 dòng docstring. CHƯA CÓ: bộ vàng (file rỗng 0 dòng). | G12: CODE: MỘT câu SQL gộp làn vector (HNSW cosine) và làn từ khoá (GIN tsvector), hợp nhất bằng RRF hằng số 60 — chỉ dùng THỨ HẠNG, không dùng điểm thô, nên không phải chuẩn hoá hai thang điểm khác nhau. Mỗi làn 30 ứng viên. SET LOCAL hnsw.ef_search=100 và hnsw.iterative_scan='relaxed_order' trong CÙNG transaction. KHÔNG 'cải tiến' RRF thành weighted sum (ADR-0006). DATA: soạn bộ vàng v1 — 40–50 cặp câu hỏi/đoạn đúng từ 20 tệp mẫu Ngày 3, đặt đúng chỗ đã chốt Ngày 1. BẮT BUỘC có trước khi đo, vì recall@5 phải có mẫu số. TEST — ĐO BASELINE (model pretrained): dense-only vs sparse-only vs hybrid, và 1 tenant vs 20 tenant. ĐÂY LÀ MỐC SO SÁNH DUY NHẤT của phần fine-tune — không đo hôm nay thì ngày mai không có gì để so. DATA fine-tune: khai thác cặp huấn luyện từ CHÍNH kho tri thức — positive = (câu hỏi sinh từ đoạn, đoạn đó), hard negative = đoạn lọt top-5 hybrid nhưng SAI (chỉ có được SAU khi hybrid chạy, nên đúng thứ tự là hôm nay); MultipleNegativesRankingLoss; tách tập giữ lại theo TÀI LIỆU không theo đoạn. CUỐI NGÀY: phóng notebook 07_finetune_embedding.ipynb lên Kaggle GPU — 3–5 giờ máy, 0 giờ người. | H12: HYBRID THẮNG DENSE-ONLY ≥ 5 ĐIỂM RECALL@5 (bảng 3 dòng); CHÊNH LỆCH RECALL@5 GIỮA 1 TENANT VÀ 20 TENANT < 3 ĐIỂM; BẢNG BASELINE recall@5 và nDCG@5 của model pretrained — cột đối chứng của toàn bộ phần fine-tune; số cặp huấn luyện khai thác được + tỉ lệ hard negative. | I12: Chưa bắt đầu
... A43: Tuần 3 | B43: Ngày 21 | C43: CN 11/10 | D43: Dev B | E43: [Nghiệm thu] Video demo 17 Use Case + slide bảo vệ | F43: Nguồn: 2 video luồng đã quay ở Ngày 14, bổ sung phần Tuần 3. | G43: Ghép video theo 3 luồng: (1) KHO TRI THỨC — UC018 tải lên, UC019 nạp 6 bước, UC020 quản lý và reindex, UC041 xoá dữ liệu cá nhân; (2) HỎI ĐÁP — UC022 định tuyến 7 nhánh, UC023 trả lời có trích dẫn, UC025 từ chối khi thiếu căn cứ, UC026 tóm tắt, UC027 đánh giá, UC014 chuyển giao; (3) KINH DOANH VÀ VẬN HÀNH — UC029 trích xuất, UC030 chấm điểm, UC031 tạo Lead, UC038 thống kê chủ đề, UC039 báo cáo chi phí, UC040 kiểm toán, UC006 hạn mức. Mỗi UC phải hiện SỐ LIỆU thật trên màn hình, không chỉ hiện giao diện. Slide bảo vệ bám theo: 3 quyết định kiến trúc lớn (hai tầng, hybrid RRF, không ghi thẳng CSDL nghiệp vụ), bảng 7 chỉ số §1.6, bảng 2 nhánh router, bảng fine-tune trước/sau, PHẠM VI 17 UC và hướng phát triển. Chuẩn bị câu trả lời cho ba câu chắc chắn được hỏi: (a) dữ liệu thử nghiệm lấy từ đâu và ranh giới trung thực của nó; (b) vì sao chọn kiến trúc hai tầng; (c) làm sao chắc chắn doanh nghiệp A không đọc được dữ liệu của B. | H43: VIDEO DEMO đi qua ĐỦ 17 UC theo 3 luồng, mỗi UC kèm số liệu; bảng ánh xạ phút:giây → UC; bộ slide; danh sách câu hỏi khó đoán trước kèm câu trả lời CÓ SỐ LIỆU. | I43: Chưa bắt đầu

Sheet Phân vai 17 Use Case
A1: PHÂN VAI 17 USE CASE — 2 NGƯỜI, 21 NGÀY (21/09 → 11/10/2026)
A2: Dev A — Kho tri thức & Trả lời (8 UC) | Dev B — Định tuyến, Nghiệp vụ & Vận hành (9 UC). Chia theo RANH GIỚI MÃ NGUỒN để hai người gần như không sửa cùng một file. Ba use case về tích hợp hệ thống ngoài qua giao thức chuẩn nằm ở sheet 'Mở rộng sau đồ án' — đề tài được duyệt không yêu cầu chúng.
A4: UC | B4: Tên use case | C4: Nhóm | D4: Mức sở hữu (đặc tả) | E4: Người phụ trách | F4: Tuần | G4: Ngày | H4: Phụ thuộc trước đó
A5: UC006 | B5: Theo dõi hạn mức sử dụng | C5: Nhóm A | D5: CHIA | E5: Dev B | F5: Tuần 3 | G5: Ngày 16 | H5: UC039
A6: UC014 | B6: Chuyển giao hội thoại sang nhân viên | C6: Nhóm B | D6: CHIA | E6: Dev B | F6: Tuần 2 | G6: Ngày 12 | H6: UC022, UC025; cần bảng handoff_events của Track A
A7: UC018 | B7: Tải lên tài liệu tri thức | C7: Nhóm C | D7: CHIA | E7: Dev A | F7: Tuần 1 | G7: Ngày 3 | H7: CSDL chạy thật (Ngày 1)
A8: UC019 | B8: Nạp và lập chỉ mục tài liệu | C8: Nhóm C | D8: AI toàn bộ | E8: Dev A | F8: Tuần 1 | G8: Ngày 4–5 | H8: UC018, encoder ONNX (Ngày 2)
A9: UC020 | B9: Quản lý kho tri thức | C9: Nhóm C | D9: CHIA | E9: Dev A | F9: Tuần 2 | G9: Ngày 11 | H9: UC019
A10: UC022 | B10: Phân loại ý định và định tuyến | C10: Nhóm D | D10: AI toàn bộ | E10: Dev B | F10: Tuần 1 | G10: Ngày 3–6 | H10: Tập test người thật (Ngày 2)
A11: UC023 | B11: Trả lời dựa trên tri thức doanh nghiệp | C11: Nhóm D | D11: AI toàn bộ | E11: Dev A | F11: Tuần 2 | G11: Ngày 9 | H11: UC019, Hybrid Search (Ngày 6), UC022, LangGraph (Ngày 8)
A12: UC025 | B12: Từ chối khi không đủ căn cứ | C12: Nhóm D | D12: AI toàn bộ | E12: Dev A | F12: Tuần 2 | G12: Ngày 10 | H12: UC023
A13: UC026 | B13: Tóm tắt nội dung hội thoại | C13: Nhóm D | D13: AI toàn bộ | E13: Dev A | F13: Tuần 2 | G13: Ngày 12 | H13: Worker Kafka (Ngày 5)
A14: UC027 | B14: Đánh giá chất lượng câu trả lời | C14: Nhóm D | D14: CHIA | E14: Dev A | F14: Tuần 2 | G14: Ngày 10 | H14: UC023, UC039
A15: UC029 | B15: Trích xuất tín hiệu quan tâm | C15: Nhóm E | D15: AI toàn bộ | E15: Dev B | F15: Tuần 2 | G15: Ngày 11 | H15: Node generate (Ngày 9)
... A21: UC041 | B21: Xử lý yêu cầu xoá dữ liệu cá nhân | C21: Nhóm F | D21: CHIA | E21: Dev A | F21: Tuần 2 | G21: Ngày 12 | H21: UC019 (chunk), UC030 (đặc trưng lead)
B23: Số UC do Dev A phụ trách | C23: 8
B24: Số UC do Dev B phụ trách | C24: 9
B25: Số UC làm trong 21 ngày | C25: 17
B26: Số UC chuyển sang sheet 'Mở rộng sau đồ án' | C26: 3
B27: Tổng số Use Case module AI theo đặc tả | C27: 20
A29: RANH GIỚI MÃ NGUỒN — THEO CÂY src/ THẬT SAU ADR-0015, ĐƯA THẲNG VÀO .github/CODEOWNERS
A30: Chủ sở hữu | B30: Đường dẫn | C30: Nội dung
A31: Dev A | B31: ai-service/src/ai/db/** | C31: session.py (SET LOCAL app.tenant_id), pool, models, repositories
A32: Dev A | B32: ai-service/src/ai/rag/** | C32: ingest, retrieve (hybrid + RRF), rerank, generate
A33: Dev A | B33: ai-service/migration/** (dải V2xx) | C33: Migration mới BẮT ĐẦU TỪ V210 — V201–V209 đã chạy, không sửa
A34: Dev A | B34: ai-service/src/ai/orchestrator/nodes/{guard,retrieve,generate,postguard}.py | C34: 4 node của đường trả lời
A35: Dev A | B35: ai-service/tests/eval/** | C35: Bộ vàng, eval harness, configs
A36: Dev A | B36: inference/src/roles/{embed,rerank}.py | C36: Hai service suy luận của đường truy hồi
A37: Dev B | B37: ai-service/src/api/** | C37: FastAPI routing, deps, eureka, OpenAPI
A38: Dev B | B38: ai-service/src/worker/** | C38: Kafka consumer, DLQ, chống trùng, trigger UC026, UC038
A39: Dev B | B39: ai-service/src/ai/{scoring,extraction,clustering}/** | C39: UC029, UC030, UC031, UC038
A40: Dev B | B40: ai-service/src/ai/{guardrails,events,telemetry}/** | C40: normalize/injection/pii, envelope sự kiện, metric
A41: Dev B | B41: ai-service/src/ai/integrations/java_core/** | C41: Mọi lời gọi sang Track A — KHÔNG nối thẳng CSDL (ADR-0002)
... A49: KHÔNG AI ĐƯỢC SỬA | B49: java-core/, gateway/, eureka-server/, web-dashboard/, web-widget/, loadtest/ | C49: Mã nguồn Track A. Cần đổi thì báo, không tự sửa

Sheet Phạm vi cắt & làm sau
A1: PHẠM VI: 17 USE CASE TRONG 21 NGÀY — MƯỜI HẠNG MỤC RÚT GỌN, KHÔNG HẠNG MỤC NÀO BỊ BỎ HẲN
A2: Hai hạng mục CHẤT LƯỢNG được giữ, cả hai dựa trên cùng một thủ thuật: GPU Kaggle chạy qua đêm nên tốn giờ máy chứ không tốn ngày làm việc. Các hạng mục còn lại rút gọn hoặc làm sau, cột cuối ghi rõ thứ tự ưu tiên và thời lượng. Đưa nguyên bảng này vào mục 'Phạm vi và hướng phát triển' của báo cáo: nói rõ rút gọn gì, vì sao, bao giờ làm tiếp MẠNH HƠN NHIỀU so với im lặng về phạm vi.
A4: Hạng mục | B4: Bản đầy đủ | C4: Bản 21 ngày | D4: Tiết kiệm | E4: Lý do và ảnh hưởng tới báo cáo | F4: Kế hoạch làm tiếp
A5: Cụm AWS EKS Production | B5: 5 node group + ALB + ACM + HPA + PDB + IRSA + rolling update/rollback | C5: 1 instance cloud CPU, docker compose kiểu production + Nginx/TLS (Ngày 18) | D5: ~9 người-ngày | E5: Đây là năng lực VẬN HÀNH, không phải chất lượng của module AI. Mọi chỉ tiêu chất lượng (recall, parity, cách ly tenant, p95) đều đo được đầy đủ trên môi trường hiện tại. Thư mục inference/k8s/ hiện chỉ có .gitkeep. | F5: ƯU TIÊN 1 — manifest và eksctl config viết sẵn được trong lúc chờ; dựng cụm + deploy + đo lại mất khoảng 4–5 ngày với 2 người.
A6: Load test đầy đủ | B6: Tải mục tiêu 50u/30 phút + đỉnh tải 150u + soak 4 giờ | C6: Baseline 10u/10 phút + tải mục tiêu 50u/15 phút (Ngày 19) + soak 1 giờ + 2 kịch bản đứt kết nối | D6: ~1 người-ngày | E6: Giữ đúng kịch bản QUYẾT ĐỊNH (50 người dùng đồng thời, p95 < 4s). Đỉnh tải 150u chỉ có nghĩa khi có autoscaling — trên một instance đơn nó chỉ làm bão hoà CPU và cho ra con số không diễn giải được. | F6: ƯU TIÊN 2 — làm CÙNG LÚC với EKS. Soak 4 giờ chạy qua đêm nên gần như 0 giờ người.
A7: Benchmark hai ma trận đầy đủ | B7: 14 dòng ma trận model × số luồng + 27 ô ma trận khối lượng rerank kèm nDCG@5 từng ô | C7: Ma trận rút gọn 3 model × 2 mức vCPU (Ngày 15) | D7: ~1 người-ngày | E7: Vẫn chứng minh được 2 điều cốt lõi: model nhỏ tăng vCPU KHÔNG cải thiện p95, và OMP_NUM_THREADS phải khớp số CPU được cấp. MẤT: độ phủ ứng viên model và bảng nDCG theo khối lượng. | F7: ƯU TIÊN 3 — script bench_cpu.py viết ở Ngày 15, chạy thêm chỉ tốn giờ máy. Khoảng 1 ngày.
A8: Bật và tinh chỉnh rerank | B8: Quét ma trận khối lượng, chọn cấu hình tối ưu, bật và đo lại | C8: Triển khai sau feature flag, MẶC ĐỊNH TẮT, đo nDCG một lần để có số liệu cho ADR (Ngày 8) | D8: ~1 người-ngày | E8: Rerank là thứ ĐẦU TIÊN bị cắt khi ngân sách độ trễ căng (§5.3 quy tắc 2) vì lợi ích của nó nhỏ hơn phương sai của LLM. Cổng quyết định vẫn được ghi vào ADR: bật production chỉ khi cho thêm ≥ 5 điểm nDCG@5 và p95 vẫn dưới 4s. | F8: ƯU TIÊN 4 — code đã có sẵn sau feature flag; sau khi có benchmark thì bật/tắt là một phép đọc bảng.
A9: Bộ kiểm thử hồi quy tự động đủ 17 UC | B9: Một lệnh chạy hết 17 UC, xuất báo cáo pass/fail theo từng UC | C9: Test của Dev B đã gom thành một lệnh (Ngày 13); phần Dev A còn chạy rời | D9: ~0,5 người-ngày | E9: Đã làm được một nửa gần như miễn phí. Phần còn lại là gom test của Dev A và viết trình chạy chung. | F9: ƯU TIÊN 5 — nửa ngày. Làm sớm thì mọi lần sửa về sau đều rẻ hơn.
A10: UC038 chạy định kỳ tự động | B10: CronJob Kubernetes hằng tuần theo từng tenant | C10: Chạy THỦ CÔNG một lần, ghim random_state, đủ số liệu cho báo cáo (Ngày 17) | D10: ~0,5 người-ngày | E10: Use case vẫn được demo đầy đủ. MẤT: phần tự động hoá lịch chạy. | F10: ƯU TIÊN 6 — làm được ngay bằng cron/systemd timer trên instance, khoảng nửa ngày, không cần chờ EKS.
A11: Ngày rà soát chéo + red-team chuyên biệt | B11: Trọn một ngày mỗi người đọc và tấn công toàn bộ phần của người kia | C11: Rà soát chéo NHẸ trong nhịp hằng ngày: không ai merge phần của mình mà không có người kia đọc qua pull request | D11: ~2 người-ngày | E11: Bản nhẹ giữ được phần lớn giá trị với chi phí gần bằng 0. MẤT: buổi red-team tập trung, nơi thường lòi ra các lỗi ở đường biên mà đọc code thường không thấy. | F11: ƯU TIÊN 7 — một ngày sau khi nộp.
A12: Mở rộng tập test người thật | B12: 250–300 câu (ADR-0016 ghi không dưới 250, giả định 3 người gõ) | C12: 200 câu, 2 người gõ + gán nhãn chéo + Cohen's kappa (Ngày 2) | D12: ~0,5 người-ngày | E12: Nhóm có 2 người chứ không phải 3. 200 câu là mức SÀN để macro-F1 còn có nghĩa — KHÔNG ĐƯỢC cắt sâu hơn. Với tập nhỏ, khoảng tin cậy bootstrap rộng hơn nên càng phải so sánh THEO CẶP chứ không so hai con số trần. Ghi rõ con số 200 và lý do vào báo cáo, đừng để người đọc tự phát hiện. | F12: ƯU TIÊN 8 — mở rộng dần. Mỗi lần bổ sung phải ĐÓNG BĂNG và ghi hash mới, giữ nguyên tập cũ để so sánh lịch sử vẫn hợp lệ.
A13: Nhánh A của router (TF-IDF + LinearSVC) | B13: 3 nhánh đối chứng A/B/C (§5.9) | C13: 2 nhánh: B (XLM-R fine-tune) và C (embedding + kNN) — Ngày 4–5 | D13: ~0,3 người-ngày | E13: Quyết định phạm vi có chủ đích, ghi vào ADR. Đánh đổi cần biết: nhánh A là baseline RẺ NHẤT và là nhánh duy nhất chắc chắn lọt ngân sách 60 ms. Bỏ A nghĩa là nếu B quá chậm thì chỉ còn C làm lưới an toàn — may là C tái dùng ai-embed nên lưới này khá chắc. | F13: TÙY CHỌN — nhánh A huấn luyện trong vài phút trên CPU, bổ sung lại chỉ tốn 1–2 giờ. Hạng mục rẻ nhất cả danh sách.
A14: Ngày đệm thuần | B14: 6 ngày đệm (bản 7 tuần) | C14: Ngày 7 để nhẹ làm đệm một phần; Ngày 14 và 21 là tích hợp + báo cáo | D14: ~3 người-ngày | E14: Vẫn căng. Một ngày trượt phải xử lý bằng CẮT ĐỘ SÂU ngay trong ngày, không được lùi sang ngày sau — vì ngày sau đã đầy. | F14: Không áp dụng — đây là hệ quả của thời hạn, không phải hạng mục kỹ thuật.
A16: HAI HẠNG MỤC CHẤT LƯỢNG ĐƯỢC GIỮ — CÙNG MỘT THỦ THUẬT: GPU CHẠY QUA ĐÊM
A17: Hạng mục GIỮ LẠI | B17: Chi phí thật | C17: Đặt ở đâu trong 21 ngày | D17: Vì sao nhét vừa | E17: Đánh đổi
A18: Fine-tune embedding trên dữ liệu miền | B18: ~1 người-ngày | C18: Ngày 6 (khai thác cặp huấn luyện + phóng GPU qua đêm) và Ngày 7 (export ONNX, cổng parity, reindex, đo lại có KTC) | D18: Huấn luyện GPU Kaggle 3–5 giờ chạy QUA ĐÊM giữa Ngày 6 và Ngày 7, và reindex toàn bộ chunk 15–30 phút chạy nền — hai việc nặng nhất tốn 0 giờ người. Chi phí thật chỉ còn export, kiểm parity và đo lại. | E18: Test tải hỗn hợp chuyển sang Ngày 7 (Dev B). Mọi con số recall/nDCG từ Ngày 8 trở đi là của bản fine-tune; baseline pretrained lưu từ Ngày 6 làm cột đối chứng.
A19: Nhánh B của router (XLM-R fine-tune) | B19: ~0,5 người-ngày | C19: Phóng GPU cuối Ngày 4, thu kết quả và so sánh hai nhánh ở Ngày 5 | D19: Cùng thủ thuật: GPU Kaggle chạy qua đêm 3–4 giờ, 0 giờ người. Chi phí thật chỉ là phần phân tích so sánh ở Ngày 5. | E19: Bỏ nhánh A để giữ khối lượng không đổi. So sánh còn hai hướng tiếp cận rõ ràng: model chuyên dụng nặng (B) và tái dùng embedding sẵn có (C) — vẫn đủ làm một bảng đối chứng có KTC cho Chương 5.
A21: KHÔNG ĐƯỢC CẮT THÊM — bốn thứ giữ lại bằng mọi giá
A22: Tập test người thật đã đóng băng | B22: Không có nó thì mọi con số macro-F1 đều là ảo — hai nhánh router đang được so trên một bài toán giả.
A23: Test cách ly tenant trong CI | B23: Rò rỉ dữ liệu giữa doanh nghiệp là lỗi không sửa được bằng lời giải thích. Là 1 trong 7 chỉ số §1.6.
A24: Bộ vàng ≥ 80 cặp | B24: Là mẫu số của recall@5 và độ phủ trích dẫn — hai chỉ số cốt lõi của UC023.
A25: Đủ 17 use case chạy được | B25: Mỗi UC phải có: endpoint/worker chạy, 1 test chứng minh luồng chính, 1 con số minh chứng. Đó là mức tối thiểu để được chấm. Giảm ĐỘ SÂU thì được, bỏ hẳn một UC thì mất điểm trực tiếp.

Sheet Mở rộng sau đồ án
A1: MỞ RỘNG SAU ĐỒ ÁN — HƯỚNG PHÁT TRIỂN, KHÔNG PHẢI PHẦN BỊ THIẾU
A2: Đề tài được duyệt yêu cầu: chatbot LLM tích hợp CRM, RAG trên dữ liệu riêng doanh nghiệp, phân loại và ghi nhận khách hàng tiềm năng, dashboard thống kê, hỗ trợ đa kênh. 17 use case trong sheet kế hoạch phủ trọn phần module AI của các yêu cầu đó. Bảng dưới đây là những thứ ĐI XA HƠN đề tài — nền móng đã dựng sẵn trong repo nên bật lên là chạy, nhưng chúng không nằm trong phạm vi nghiệm thu. Đưa nguyên bảng này vào chương cuối của báo cáo.
A4: Hướng mở rộng | B4: Nền móng ĐÃ CÓ sẵn trong repo | C4: Còn phải làm gì | D4: Thời lượng ước tính | E4: Vì sao không nằm trong 21 ngày
A5: Tích hợp hệ thống nghiệp vụ thời gian thực qua giao thức chuẩn MCP — UC021, UC024, UC028 | B5: Bảng integration.mcp_servers và ai.ai_tool_calls đã tạo trong V205 (97 dòng) và V208 (ràng buộc cấu trúc tool_schema_cache), có RLS FORCE và chỉ mục đầy đủ — chỉ đang rỗng. ADR-0005 đã chốt hướng. .claude/rules/mcp.md đã ghi ba lớp danh sách trắng, quy tắc ghim spec_version, quy tắc kiểm toán mọi lời gọi kể cả lần bị chặn. docs/openapi/ai-service-to-java-core.yaml đã khai các path /v1/mcp-servers, /v1/tools, /v1/tool-calls. Master Plan §2.7 mô tả đủ 7 bước. Nhánh ý định 'gọi công cụ' VẪN nằm trong taxonomy 7 nhánh của UC022 và vẫn được phân loại đúng. | C5: UC021 cấu hình máy chủ + sổ đăng ký công cụ (1 ngày) · UC024 vòng lặp gọi công cụ tối đa 10 lượt + idempotency key (1 ngày) · UC028 ba lớp danh sách trắng + 6 lý do chặn, đấu nối máy chủ thật và kiểm thử phủ định cả ba lớp (1 ngày). Không có rủi ro thiết kế vì hợp đồng và lược đồ đã chốt. | D5: 3 ngày, làm liền một mạch | E5: Đề tài được duyệt KHÔNG nhắc tới MCP. Đây cũng là nhóm duy nhất mà giá trị demo phụ thuộc vào một hệ thống bên ngoài (máy chủ MCP ở repo riêng mcp-server-mock). Trong 21 ngày, ba ngày đó đổi được lấy chiều sâu cho các use case mà đề tài thực sự yêu cầu.
A6: Hoàn thiện kiểm toán khi có tích hợp công cụ | B6: UC040 đã làm đủ phần áp dụng được: 4 loại tác nhân, 3 mức nghiêm trọng, che PII ở tầng ghi, thu hồi quyền sửa và xoá trên bảng kiểm toán. Hàm hợp nhất nguồn cảnh báo viết sẵn dạng mở rộng được (Ngày 16). Cột guard_latency_ms trên ai_tool_calls đã có từ V209. | C6: Bật nguồn cảnh báo thứ hai (lời gọi công cụ bị chặn) vào hàm hợp nhất. Không phải sửa lược đồ. | D6: Nửa ngày, sau khi có UC028 | E6: Trong phạm vi đồ án, nguồn cảnh báo an toàn là safety_flag trên ai_interactions — đã đủ để demo và đo.
A7: Bài kiểm thử bảo mật 'quyền công cụ' | B7: 5 bài còn lại đã chạy ở Ngày 17 (cách ly tenant qua ngôn ngữ, cách ly cache, PII trong log, payload không định danh, bộ adversarial). | C7: Bài thứ 6: kiểm thử phủ định ba lớp danh sách trắng — tool lạ do máy chủ quảng cáo, tool đã tắt theo doanh nghiệp, tool không thuộc ý định hiện tại. | D7: Nửa ngày, sau khi có UC028 | E7: Không có lời gọi công cụ thì không có gì để kiểm. Trong bảng chỉ số ghi 'không áp dụng' kèm lý do chứ ĐỪNG để ô trống — ô trống đọc như một bài đã bỏ sót.
A8: Đa kênh Zalo và Facebook Messenger | B8: Kiến trúc đã tách kênh khỏi lõi AI: ai_interactions có cột kênh, bảng tổng hợp theo ngày có chiều kênh. Kế hoạch 19 tuần của đồ án đã chốt chỉ tích hợp MỘT kênh, kênh còn lại thiết kế trên giấy qua giao diện ChannelAdapter. | C8: Webhook + xác thực chữ ký + ánh xạ định danh người dùng của kênh thứ hai. Đây là việc của Track A, module AI không phải sửa gì. | D8: ~1 tuần-người (Track A) | E8: Đã là quyết định phạm vi của kế hoạch 19 tuần, không phải của 21 ngày này. Module AI phục vụ kênh nào cũng như nhau vì đã tách bạch.
A9: Thử nghiệm trên dữ liệu doanh nghiệp thật | B9: Toàn bộ đường ống nạp tài liệu (UC018–UC020) và quy trình ẩn danh hoá đã sẵn sàng. Ngày 18 có một chỗ dành riêng để nạp nếu xin được dữ liệu. | C9: Liên hệ doanh nghiệp, xin cam kết bằng văn bản, ẩn danh hoá theo Nghị định 13/2023/NĐ-CP, nạp và đo lại recall@5 trên bộ vàng dựng từ tài liệu thật. | D9: 2–3 ngày, phần lớn là chờ | E9: Chuẩn đầu ra của đề tài có yêu cầu này. Nhóm đang dùng dữ liệu tự soạn/công khai và PHẢI ghi rõ ranh giới trung thực đó trong báo cáo. Đây là hạng mục nên ưu tiên nhất nếu có thêm thời gian.
A10: Triển khai trên cụm Kubernetes | B10: Hai Dockerfile, compose.inference.yml với requests==limits và healthcheck /ready, cấp vCPU đã chốt bằng benchmark ở Ngày 15. | C10: Manifest EKS, ALB, ACM, HPA, PDB, IRSA, rolling update/rollback. Xem thêm sheet 'Phạm vi cắt & làm sau'. | D10: 4–5 ngày với 2 người | E10: Năng lực vận hành, không phải chất lượng module AI. Mọi chỉ tiêu §1.6 đều đo được trên một instance.

Sheet Bảng theo dõi
A1: BẢNG THEO DÕI TIẾN ĐỘ — 21 NGÀY × 2 NGƯỜI = 42 ĐẦU VIỆC
A2: Mọi ô số tính bằng công thức từ sheet 'Kế hoạch 21 ngày'. Chỉ cần cập nhật cột Tiến độ ở sheet đó. Lưu ý: file được sinh bằng script nên Excel/Numbers sẽ tính công thức LẦN ĐẦU khi bạn mở — nếu thấy ô trống thì bấm lưu một lần là có số.
A4: Tuần | B4: Trọng tâm | C4: Tổng đầu việc | D4: Chưa bắt đầu | E4: Đang làm | F4: Hoàn thành | G4: Trễ hạn | H4: % Hoàn thành
A5: Tuần 1 | B5: NỀN MÓNG CHẠY THẬT + KHO TRI THỨC + ROUTER 2 NHÁNH — A: chạy migration V201–V209, test RLS, session+RLS, encoder ONNX, UC018, UC019, Hybrid Search, FINE-TUNE EMBEDDING · B: chốt 4 mâu thuẫn hợp đồng, tầng suy luận thật, tập test người thật, UC022 (nhánh B + nhánh C) · Ngày 7 để nhẹ làm đệm | C5: =COUNTIF('Kế hoạch 21 ngày'!$A$2:$A$43,A5) | D5: =COUNTIFS('Kế hoạch 21 ngày'!$A$2:$A$43,$A5,'Kế hoạch 21 ngày'!$I$2:$I$43,"Chưa bắt đầu") | E5: =COUNTIFS('Kế hoạch 21 ngày'!$A$2:$A$43,$A5,'Kế hoạch 21 ngày'!$I$2:$I$43,"Đang làm") | F5: =COUNTIFS('Kế hoạch 21 ngày'!$A$2:$A$43,$A5,'Kế hoạch 21 ngày'!$I$2:$I$43,"Hoàn thành") | G5: =COUNTIFS('Kế hoạch 21 ngày'!$A$2:$A$43,$A5,'Kế hoạch 21 ngày'!$I$2:$I$43,"Trễ hạn") | H5: =IF(C5=0,0,F5/C5)
A6: Tuần 2 | B6: LUỒNG CHÍNH + NGHIỆP VỤ AI (11 UC) — A: LangGraph 8 node, UC023, UC025, UC027, UC020, UC026, UC041, eval harness · B: AgentState, node route/fastpath/telemetry, UC030, UC029, UC031, UC014 | C6: =COUNTIF('Kế hoạch 21 ngày'!$A$2:$A$43,A6) | D6: =COUNTIFS('Kế hoạch 21 ngày'!$A$2:$A$43,$A6,'Kế hoạch 21 ngày'!$I$2:$I$43,"Chưa bắt đầu") | E6: =COUNTIFS('Kế hoạch 21 ngày'!$A$2:$A$43,$A6,'Kế hoạch 21 ngày'!$I$2:$I$43,"Đang làm") | F6: =COUNTIFS('Kế hoạch 21 ngày'!$A$2:$A$43,$A6,'Kế hoạch 21 ngày'!$I$2:$I$43,"Hoàn thành") | G6: =COUNTIFS('Kế hoạch 21 ngày'!$A$2:$A$43,$A6,'Kế hoạch 21 ngày'!$I$2:$I$43,"Trễ hạn") | H6: =IF(C6=0,0,F6/C6)
A7: Tuần 3 | B7: ĐO ĐẠC + TRIỂN KHAI + NGHIỆM THU — A: benchmark, giảm image xuống <400 MB, bảo mật, triển khai, load test, báo cáo · B: UC039, UC040, UC006, UC038, tích hợp Track A, soak, video demo 17 UC | C7: =COUNTIF('Kế hoạch 21 ngày'!$A$2:$A$43,A7) | D7: =COUNTIFS('Kế hoạch 21 ngày'!$A$2:$A$43,$A7,'Kế hoạch 21 ngày'!$I$2:$I$43,"Chưa bắt đầu") | E7: =COUNTIFS('Kế hoạch 21 ngày'!$A$2:$A$43,$A7,'Kế hoạch 21 ngày'!$I$2:$I$43,"Đang làm") | F7: =COUNTIFS('Kế hoạch 21 ngày'!$A$2:$A$43,$A7,'Kế hoạch 21 ngày'!$I$2:$I$43,"Hoàn thành") | G7: =COUNTIFS('Kế hoạch 21 ngày'!$A$2:$A$43,$A7,'Kế hoạch 21 ngày'!$I$2:$I$43,"Trễ hạn") | H7: =IF(C7=0,0,F7/C7)
A8: TỔNG | B8: Toàn module AI — 3 tuần × 7 ngày × 2 người | C8: =SUM(C5:C7) | D8: =SUM(D5:D7) | E8: =SUM(E5:E7) | F8: =SUM(F5:F7) | G8: =SUM(G5:G7) | H8: =IF(C8=0,0,F8/C8)
A10: TIẾN ĐỘ THEO TỪNG NGƯỜI
A11: Người | B11: Vai trò | C11: Tổng đầu việc | D11: Chưa bắt đầu | E11: Đang làm | F11: Hoàn thành | G11: Trễ hạn | H11: % Hoàn thành
A12: Dev A | B12: Kho tri thức & Trả lời — UC018, 019, 020, 023, 025, 026, 027, 041 (8 UC) + hạ tầng CSDL, RAG, fine-tune, benchmark, triển khai, load test | C12: =COUNTIF('Kế hoạch 21 ngày'!$D$2:$D$43,A12) | D12: =COUNTIFS('Kế hoạch 21 ngày'!$D$2:$D$43,$A12,'Kế hoạch 21 ngày'!$I$2:$I$43,"Chưa bắt đầu") | E12: =COUNTIFS('Kế hoạch 21 ngày'!$D$2:$D$43,$A12,'Kế hoạch 21 ngày'!$I$2:$I$43,"Đang làm") | F12: =COUNTIFS('Kế hoạch 21 ngày'!$D$2:$D$43,$A12,'Kế hoạch 21 ngày'!$I$2:$I$43,"Hoàn thành") | G12: =COUNTIFS('Kế hoạch 21 ngày'!$D$2:$D$43,$A12,'Kế hoạch 21 ngày'!$I$2:$I$43,"Trễ hạn") | H12: =IF(C12=0,0,F12/C12)
A13: Dev B | B13: Định tuyến, Nghiệp vụ & Vận hành — UC006, 014, 022, 029, 030, 031, 038, 039, 040 (9 UC) + hợp đồng, tầng suy luận, CI, telemetry, tích hợp Track A | C13: =COUNTIF('Kế hoạch 21 ngày'!$D$2:$D$43,A13) | D13: =COUNTIFS('Kế hoạch 21 ngày'!$D$2:$D$43,$A13,'Kế hoạch 21 ngày'!$I$2:$I$43,"Chưa bắt đầu") | E13: =COUNTIFS('Kế hoạch 21 ngày'!$D$2:$D$43,$A13,'Kế hoạch 21 ngày'!$I$2:$I$43,"Đang làm") | F13: =COUNTIFS('Kế hoạch 21 ngày'!$D$2:$D$43,$A13,'Kế hoạch 21 ngày'!$I$2:$I$43,"Hoàn thành") | G13: =COUNTIFS('Kế hoạch 21 ngày'!$D$2:$D$43,$A13,'Kế hoạch 21 ngày'!$I$2:$I$43,"Trễ hạn") | H13: =IF(C13=0,0,F13/C13)
A15: BA MỐC KIỂM SOÁT — TRƯỢT MỐC LÀ CẮT ĐỘ SÂU NGAY, KHÔNG LÙI LỊCH
A16: Mốc | B16: Hạn | C16: Điều kiện thoát và hành động khi trượt | D16: Trạng thái
A17: M1 — Nền móng + dữ liệu | B17: Hết Ngày 7 (CN 27/09) | C17: A: nạp được tài liệu thật vào knowledge.knowledge_chunks · test cách ly tenant XANH trong CI · hybrid thắng dense-only ≥ 5 điểm recall@5 · cổng parity fine-tune ≥ 0,995. B: router chạy trong ai-classify · đã chốt nhánh ship kèm ADR · tập test người thật 200 mẫu đã đóng băng · 4 mâu thuẫn hợp đồng đã chốt thành ADR-0017. TRƯỢT → cắt rerank khỏi Ngày 8 và bỏ semantic cache ở Ngày 16. | H17: Chưa bắt đầu
A18: M2 — 17/17 UC chạy được | B18: Hết Ngày 14 (CN 04/10) | C18: Mọi UC có endpoint hoặc worker chạy + 1 test luồng chính + 1 con số minh chứng; đã quay được demo luồng trả lời và demo luồng lead. TRƯỢT → cắt UC038 (Ngày 17) và dồn Ngày 15–16 sang hoàn thiện UC còn thiếu. | H18: Chưa bắt đầu
A19: M3 — Nghiệm thu | B19: Hết Ngày 21 (CN 11/10) | C19: 7/7 chỉ số §1.6 điền đủ · video demo đi qua 17 UC · báo cáo + gói bàn giao 7 hạng mục · dung lượng image ai-service < 400 MB. TRƯỢT → nộp bản có bảng chỉ số ghi rõ chỉ số nào chưa đo và vì sao; KHÔNG để trống ô nào. | H19: Chưa bắt đầu

Sheet Chỉ số nghiệm thu
A1: BẢNG CHỈ SỐ NGHIỆM THU — DÙNG TRỰC TIẾP CHO BÁO CÁO
A2: Ô TÔ VÀNG là ô phải điền: 'Giá trị đo được' và 'Kết luận'. Dòng 4 là VÍ DỤ minh hoạ định dạng — xoá trước khi nộp. Đo xong là điền ngay, đừng để dồn tới Ngày 20: số đo không ghi lại là số đo đã mất.
A4: Nhóm | B4: Chỉ số | C4: Ngưỡng đạt (theo tài liệu) | D4: Giá trị đo được | E4: Đo ở Ngày | F4: Người chịu trách nhiệm | G4: Nguồn tài liệu | H4: Kết luận
A5: VÍ DỤ | B5: p95 độ trễ endpoint chat (mẫu điền) | C5: < 4.000 ms và KHÔNG tăng dần | D5: 3.180 ms — 50 người dùng, 15 phút, độ dốc +0,4% | E5: Ngày 19 | F5: Dev A | G5: Master Plan §1.6 | H5: Đạt
A6: 7 chỉ số §1.6 | B6: p95 độ trễ endpoint chat | C6: < 4.000 ms và KHÔNG tăng dần | E6: Ngày 19 | F6: Dev A | G6: Master Plan §1.6, §5.3
A7: 7 chỉ số §1.6 | B7: Tổng p95 phần suy luận CPU | C7: < 480 ms (classify 60 + embed 120 + rerank 300) | E7: Ngày 13, 15 | F7: Dev A | G7: Master Plan §1.6, §5.3
A8: 7 chỉ số §1.6 | B8: Tỉ lệ lượt không gọi LLM | C8: ≥ 55% | E8: Ngày 8, 20 | F8: Dev B | G8: Master Plan §1.6; UC022
A9: 7 chỉ số §1.6 | B9: recall@5 trên bộ vàng | C9: ≥ 0,85 (bộ vàng ≥ 80 cặp) | E9: Ngày 13, 20 | F9: Dev A | G9: Master Plan §1.6; UC023
A10: 7 chỉ số §1.6 | B10: Độ phủ trích dẫn | C10: ≥ 0,80 | E10: Ngày 13, 20 | F10: Dev A | G10: Master Plan §1.6; UC023
A11: 7 chỉ số §1.6 | B11: Rò rỉ dữ liệu giữa tenant | C11: 0 trường hợp | E11: Ngày 1, 7, 17, 18 | F11: Dev A | G11: Master Plan §1.6, §4.3; ADR-0001
A12: 7 chỉ số §1.6 | B12: Image ai-service sạch ML runtime | C12: pip list | grep -E 'onnxruntime|torch|xgboost' RỖNG | E12: Ngày 1, 20 | F12: Dev B | G12: ADR-0015 mục 4 (bản 3 gói)
A13: Hợp đồng | B13: Chốt một bộ tên endpoint | C13: service.py và docs/openapi/ dùng CÙNG một bộ; redocly lint xanh | E13: Ngày 1 | F13: Dev B | G13: ADR-0017; ADR-0015 §1
A14: Hợp đồng | B14: Chốt bộ tên topic Kafka | C14: create-topics.sh và docs/events/ khớp nhau; có topic cho vòng phản hồi outcome | E14: Ngày 1 | F14: Dev B | G14: ADR-0017; docs/contracts/README.md
A15: Hợp đồng | B15: Đề xuất 3 cột lead_scores đã gửi Track A | C15: Gửi trong Ngày 1, có phản hồi trước Ngày 9 | E15: Ngày 1 | F15: Dev B | G15: ADR-0016 QĐ2
A16: Hạ tầng | B16: Flyway V201–V209 chạy sạch | C16: 9 dòng trong flyway_schema_history, 6 bảng, đủ chỉ mục | E16: Ngày 1 | F16: Dev A | G16: ai-service/migration/
A17: Hạ tầng | B17: Test cách ly tenant trong CI | C17: 3/3 ca xanh: đọc chéo rỗng, fail-closed khi không SET LOCAL, current_user = ai_app | E17: Ngày 1 | F17: Dev A | G17: ADR-0001, ADR-0016 QĐ1
... A59: Chất lượng | B59: Eval harness tái lập được | C59: Chạy 2 lần ra cùng con số; mỗi số liệu kèm file config | E59: Ngày 13, 20 | F59: Dev A | G59: rule rag-eval.md
B61: Số chỉ số đã ĐẠT | C61: =COUNTIF(H6:H59,"Đạt")
B62: Tổng số chỉ số theo dõi (không tính dòng VÍ DỤ) | C62: 54
B63: Trong đó: 7 chỉ số nghiệm thu §1.6 | C63: =COUNTIF(A6:A59,"7 chỉ số §1.6")

Sheet Hướng dẫn & Ghi chú
A1: KẾ HOẠCH 21 NGÀY — 2 NGƯỜI — 17 USE CASE MODULE AI
A2: Ngày 1 = 21/09/2026 (T2) · Ngày 21 = 11/10/2026 (CN) · 21 ngày lịch liên tục. Soạn ngày 20/09/2026 từ trạng thái THẬT của repo (xem sheet 'Trạng thái xuất phát'). Nguồn: MASTER_PLAN_AI_CRM_v8, Đặc tả Use Case Module AI, ADR-0015 và ADR-0016.
B4: 1. ĐỌC TRƯỚC KHI BẮT ĐẦU — MỨC ĐỘ CĂNG CỦA LỊCH NÀY
B5: Con số trần trụi | C5: 42 người-ngày cho 17 use case + nền móng + báo cáo, tức khoảng 2 người-ngày mỗi use case đã tính cả hạ tầng. Lịch này chỉ khả thi nếu cả hai làm toàn thời gian, ngày dài, và KHÔNG có ngày đệm thuần nào.
B6: Điểm xuất phát không phải số 0 | C6: Repo đã có 9 file migration chạy được, RLS FORCE trên 6 bảng, CI với cổng chặn ML runtime, hai Dockerfile, cấu hình + log + metric + DI. Nhưng code AI thì gần như chưa có dòng nào: 30/42 file Python chỉ là docstring, tests/ có 0 test, inference/ chạy là crash. ĐỌC SHEET 'Trạng thái xuất phát' TRƯỚC.
B7: Mức hoàn thành tối thiểu mỗi UC | C7: Endpoint hoặc worker chạy được + 1 test chứng minh luồng chính + 1 con số minh chứng. Đạt ba thứ đó là UC được tính. ĐỪNG làm sâu hơn mức này cho tới khi cả 17 UC đều đạt.
B8: Không còn đệm | C8: Chỉ có 3 ngày tích hợp + báo cáo (Ngày 7, 14, 21) và chúng cũng là ngày làm việc. Một ngày trượt phải xử lý bằng CẮT ĐỘ SÂU ngay trong ngày, không được lùi sang ngày sau — vì ngày sau đã đầy.
B10: 2. BẢY ĐIỀU ĐÃ CHỐT BỞI ADR-0015 VÀ ADR-0016 — ĐỪNG MỞ LẠI
B11: Số chiều vector = 1024 | C11: KHÔNG phải 768 như Master Plan §4.2. Cột embedding vector(1024) đã tồn tại trong V203 dòng 17. Hệ quả: encoder chọn ở Ngày 2 PHẢI cho ra 1024 chiều.
B12: Schema kho tri thức = knowledge.knowledge_* | C12: knowledge.knowledge_documents và knowledge.knowledge_chunks, KHÔNG phải ai.documents / ai.chunks như Master Plan viết. Bản kế hoạch cũ ghi sai chỗ này ở nhiều dòng.
B13: Công cụ migration = Flyway dải V2xx | C13: KHÔNG phải Alembic như §3.9.2 vẽ. V201–V209 đã viết xong và phải chạy được ở Ngày 1. Migration mới BẮT ĐẦU TỪ V210. Không bao giờ ghi vào dải V1xx của Track A.
B14: Cổng chặn CI = 3 gói | C14: onnxruntime | torch | xgboost. KHÔNG phải bản 6 gói của §3.2 và cũng không phải bản 5 gói của .claude/rules/ai-service.md. Lý do: scikit-learn là phụ thuộc GIÁN TIẾP của pyvi mà rag/tsquery cần. Luật vẫn giữ: cấm import sklearn trong src/ để suy luận.
B15: Role runtime = ai_app | C15: KHÔNG phải ai_service như Master Plan §4.2/§4.3 viết. Tính chất quan trọng không phải cái tên mà là role runtime KHÔNG ĐƯỢC là chủ bảng — chủ bảng bypass RLS kể cả khi đã FORCE. crm_owner chỉ dành cho Flyway.
B16: Không tạo bảng ai.lead_features | C16: Master Plan §5.10.2 mô tả bảng này nhưng nó chưa từng được tạo và sẽ không tạo. Nhãn huấn luyện nằm ở sales.lead_scores của Track A + 3 cột rule_score/outcome/outcome_at đề xuất thêm. ai-service ghi QUA API, KHÔNG ghi thẳng (ADR-0002).
B17: Bố cục src/ chứ không app/ | C17: src/ai/service.py là FACADE DUY NHẤT; schemas.py là một FILE chứ không phải thư mục; src/ai/ không import src.api hay src.worker; api/ và worker/ không import chéo. CI kiểm hai luật này bằng grep.
B19: 3. BỐN THỨ PHẢI CHỐT TRONG NGÀY 1 — KHÔNG ĐƯỢC HOÃN
B20: Một bộ tên endpoint | C20: Hiện LỆCH hai bộ: src/ai/service.py ghi /v1/ai/chat, /v1/ai/kb/documents; hợp đồng trong docs/openapi/ ghi /v1/answer, /v1/documents/ingest. Route đầu tiên viết ở Ngày 3 — chốt muộn thì phải sửa cả code lẫn hợp đồng lẫn phần Track A đã gọi.
B21: Bộ tên topic Kafka | C21: Repo có 5 topic crm.*.v1, Master Plan §2.6 khai 8. Bản kế hoạch trước hoãn việc này tới 'Ngày 12' — không hoãn được nữa vì consumer đầu tiên viết ở Ngày 5. Nhớ thêm topic cho vòng phản hồi khi deal đóng: nó KHÔNG có trong cả hai bộ hiện tại mà UC030 cần nó ở Ngày 18.
B22: Chỗ đặt bộ vàng | C22: tests/eval/golden_set.jsonl (theo .claude/rules/rag-eval.md) hay data/golden_qa.jsonl (theo CLAUDE.md gốc)? Hai chỗ đang song song, một file rỗng một file chưa tồn tại. Chọn MỘT và xoá nhắc tới cái kia.
B23: Cỡ tập test người thật | C23: ADR-0016 ghi không dưới 250 mẫu, dựa trên giả định 3 người gõ. Nhóm có 2 người và lịch 21 ngày chỉ vừa 200. Chốt 200 và GHI RÕ lý do vào ADR phạm vi + báo cáo. Im lặng rồi nộp 200 mới là thứ mất điểm, chứ không phải bản thân con số 200.
B25: 4. VÌ SAO MCP NẰM Ở SHEET 'MỞ RỘNG SAU ĐỒ ÁN'
B26: Lý do chính | C26: Đề tài được duyệt không nhắc tới MCP. Mô tả, mục tiêu và chuẩn đầu ra của đề tài yêu cầu: chatbot LLM tích hợp CRM, RAG trên dữ liệu riêng doanh nghiệp, phân loại và ghi nhận khách hàng tiềm năng, dashboard thống kê, đa kênh. 17 use case trong sheet kế hoạch phủ trọn phần module AI của các yêu cầu đó.
B27: Lý do kỹ thuật | C27: Đây là nhóm duy nhất trong 20 UC mà giá trị demo phụ thuộc vào một hệ thống BÊN NGOÀI (máy chủ MCP ở repo riêng mcp-server-mock). Ba use case UC021/UC024/UC028 chỉ có giá trị khi đi cùng nhau, nên tách cả nhóm gọn hơn nhiều so với làm dở một phần.
B28: Cách nói khi bảo vệ | C28: Không nói 'chúng em chưa kịp làm'. Nói: phạm vi đồ án là 17 use case và đã hoàn thành 17/17; phần tích hợp hệ thống nghiệp vụ thời gian thực qua giao thức chuẩn là HƯỚNG PHÁT TRIỂN, nền móng đã dựng sẵn (bảng integration.mcp_servers và ai.ai_tool_calls đã có trong migration, ADR-0005 đã chốt hướng, hợp đồng đã khai trong OpenAPI), lộ trình 3 ngày.
B29: Một thứ KHÔNG được cắt theo | C29: Nhánh ý định 'gọi công cụ' VẪN GIỮ NGUYÊN trong taxonomy 7 nhánh của UC022 và vẫn được phân loại đúng, chỉ là định tuyến sang chuyển giao với lý do 'cần duyệt thao tác ghi'. Cắt nhánh khỏi taxonomy sẽ làm lệch toàn bộ số liệu telemetry và phải huấn luyện lại router nếu sau này mở rộng.
B31: 5. AI LÀM GÌ
B32: Dev A | C32: KHO TRI THỨC & TRẢ LỜI — 8 UC: UC018, UC019, UC020, UC023, UC025, UC026, UC027, UC041. Kiêm hạ tầng CSDL, RLS, model nhúng, hybrid search, 4 node guard/retrieve/generate/postguard, eval harness, benchmark, triển khai, load test.
B33: Dev B | C33: ĐỊNH TUYẾN, NGHIỆP VỤ & VẬN HÀNH — 9 UC: UC006, UC014, UC022, UC029, UC030, UC031, UC038, UC039, UC040. Kiêm hợp đồng API và Kafka, tầng suy luận, CI, router 2 nhánh, lead scoring, trích xuất, telemetry, 4 node route/fastpath/handoff/telemetry, tích hợp Track A.
B34: Đổi thành tên thật | C34: Ctrl+H trên sheet 'Kế hoạch 21 ngày': thay 'Dev A' và 'Dev B'. Nhớ thay ở CẢ các sheet 'Phân vai', 'Bảng theo dõi', 'Chỉ số nghiệm thu' và sheet ẩn 'Danh mục' thì COUNTIFS mới khớp.
B36: 6. BỐN ĐIỂM HAI ĐƯỜNG GẶP NHAU — DỄ VỠ NHẤT
B37: Ngày 1 — Bốn quyết định hợp đồng | C37: Cả hai người đều phụ thuộc vào chúng. Ngồi cùng nhau chốt trong buổi sáng, viết thành ADR-0017 ngay trong ngày.
B38: Ngày 2 — Buổi chung gõ tập test | C38: 3 giờ, cả hai cùng gõ. Đây là tài sản giá trị nhất của phần thực nghiệm. Gán nhãn ĐỘC LẬP rồi mới đối chiếu.
B39: Ngày 8 — AgentState + LangGraph | C39: Hai người NGỒI CÙNG NHAU chốt cấu trúc AgentState TRƯỚC KHI ai code node nào. Quy tắc: mỗi người chỉ ĐĂNG KÝ node của mình vào registry, KHÔNG sửa node của người kia. Vi phạm quy tắc này là nguồn conflict số một.
B40: Ngày 9 — Node generate | C40: Dev B cần node generate của Dev A cho UC029 (Ngày 11). Nếu Ngày 9 trượt, Dev B đảo lịch ngay: làm UC031/UC014 trước, UC029 sau.
B42: 7. HAI HẠNG MỤC CHẤT LƯỢNG ĐƯỢC GIỮ — GPU CHẠY QUA ĐÊM
B43: Thủ thuật chung | C43: Cả hai đều dựa trên GPU Kaggle chạy QUA ĐÊM: việc nặng tốn giờ máy chứ không tốn ngày làm việc. Phóng cuối ngày hôm trước, thu kết quả sáng hôm sau.
B44: Nhánh B router — Ngày 4–5 | C44: Cuối Ngày 4 phóng notebook fine-tune XLM-R base lên GPU (3–4 giờ). Ngày 5 thu kết quả, so hai nhánh bằng paired bootstrap KTC 95%, chốt nhánh ship, chọn ngưỡng abstention, export ONNX vào ai-classify.
B45: Fine-tune embedding — Ngày 6–7 | C45: Ngày 6 khai thác cặp huấn luyện rồi phóng GPU (3–5 giờ). Ngày 7 thu kết quả, export ONNX INT8, chạy cổng parity, reindex toàn bộ chunk, đo lại có KTC. Từ Ngày 8 mọi truy hồi chạy trên bản fine-tune.
B46: Thứ tự BẮT BUỘC của fine-tune | C46: Hybrid Search phải xong TRƯỚC khi khai thác dữ liệu, vì hard negative là những đoạn lọt top-5 hybrid nhưng SAI — không có hybrid thì không có hard negative, mà không có hard negative thì fine-tune gần như không cải thiện gì.
B47: Bẫy tách tập | C47: Tách tập giữ lại theo TÀI LIỆU, không theo đoạn. Tách theo đoạn thì các đoạn cùng một tài liệu lọt cả hai bên, model học thuộc văn phong tài liệu đó và chỉ số bị thổi phồng.
...
